Workbook

Sheet ALBO DORO
B1: CAMPIONATO | E1: COPPA
A2: ANNO | B2: PRIMO | C2: SECONDO | D2: TERZO | E2: CAMPIONE COPPA | F2: VICE CAMPIONE COPPA
A3: 2018 | B3: FATTE | C3: PIEGRO | D3: LOMBA
A4: 2019 | B4: TAFFO | C4: PIEGRO | D4: LOMBA | E4: TAFFO | F4: LOMBA
A5: 2020 | B5: FATTE | C5: ALFIO | D5: CASSI | E5: CASSI | F5: ALFIO
A6: 2021 | B6: ALFIO | C6: FATTE | D6: TAFFO | E6: ALFIO | F6: FORE
A7: 2022 | B7: FATTE | C7: ALFIO | D7: LOMBA | E7: LOMBA | F7: TAFFO
A8: 2023 | B8: TAFFO | C8: FATTE | D8: PIEGRO | E8: LOMBA | F8: TAFFO
A9: 2024 | B9: TAFFO | C9: LOMBA | D9: PIEGRO | E9: ALE | F9: FUSTO
A10: 2026 | B10: FUSTO | C10: TAFFO | D10: BURNEY | E10: TAFFO | F10: LOMBA
A11: 2026

Sheet ROSE 2021
H1: FANTAGHEIS 2020-2021
C4: TAFFO | G4: FORE | K4: CASSI | O4: ALFIO | S4: ALE
C5: GIOCATORE | E5: PREZZO | F5: TOT | G5: GIOCATORE | I5: PREZZO | J5: TOT | K5: GIOCATORE | M5: PREZZO | N5: TOT | O5: GIOCATORE | Q5: PREZZO | R5: TOT | S5: GIOCATORE | U5: PREZZO | V5: TOT
C6: handanovic | E6: 46 | G6: Ospina | I6: 27 | K6: pau lopez | M6: 10 | O6: gollini | Q6: 31 | S6: sepe | U6: 11
B7: POR | C7: padelli | E7: 1 | G7: meret | I7: 17 | K7: mirante | M7: 18 | O7: sirigu | Q7: 7 | S7: skoruspski | U7: 1
C8: montipo | E8: 1 | F8: =SUM(E6:E8) -> 48 | G8: consigli | I8: 6 | J8: =SUM(I6:I8) -> 50 | K8: cordaz | M8: 1 | N8: =SUM(M6:M8) -> 29 | O8: perin | Q8: 7 | R8: =SUM(Q6:Q8) -> 45 | S8: colombi | U8: 1 | V8: =SUM(U6:U8) -> 13
C9: djimsiti | E9: 9 | G9: romagnoli | I9: 21 | K9: milenkovic | M9: 21 | O9: criscito | Q9: 28 | S9: acerbi | U9: 30
C10: bastoni | E10: 15 | G10: gosens | I10: 44 | K10: toloi | M10: 10 | O10: faraoni | Q10: 18 | S10: alex sandro | U10: 17
C11: young | E11: 16 | G11: godin | I11: 15 | K11: smalling | M11: 13 | O11: manolas | Q11: 18 | S11: gagliolo | U11: 9
B12: DIF | C12: cuadrado | E12: 19 | G12: mario rui | I12: 2 | K12: zappacosta | M12: 6 | O12: pezzella | Q12: 6 | S12: luis felipe | U12: 3
C13: patric | E13: 1 | G13: osorio | I13: 1 | K13: calabria | M13: 2 | O13: toljan | Q13: 3 | S13: caldirola | U13: 4
C14: hysaj | E14: 4 | G14: izzo | I14: 3 | K14: demiral | M14: 2 | O14: strygen larsen | Q14: 4 | S14: bremer | U14: 3
C15: bruno alves | E15: 3 | G15: lykpogiannis | I15: 1 | K15: muldur | M15: 3 | O15: maksimovic | Q15: 1 | S15: darmian | U15: 1
C16: reca | E16: 1 | F16: =SUM(E9:E16) -> 68 | G16: yoshida | I16: 1 | J16: =SUM(I9:I16) -> 88 | K16: romero | M16: 1 | N16: =SUM(M9:M16) -> 58 | O16: walukjevic | Q16: 1 | R16: =SUM(Q9:Q16) -> 79 | S16: klavan | U16: 1 | V16: =SUM(U9:U16) -> 68
C17: milinkovic savic | E17: 52 | G17: chalanoglu | I17: 56 | K17: de paul | M17: 41 | O17: luis alberto | Q17: 60 | S17: pasalic | U17: 37
C18: chiesa | E18: 30 | G18: de roon | I18: 15 | K18: veretout | M18: 60 | O18: mkchitaryan | Q18: 40 | S18: castovilli | U18: 27
C19: sensi | E19: 18 | G19: kessie | I19: 20 | K19: zielinski | M19: 18 | O19: verre | Q19: 5 | S19: djuricic | U19: 27
B20: CEN | C20: kucka | E20: 18 | G20: tonali | I20: 8 | K20: freuler | M20: 12 | O20: bentancur | Q20: 7 | S20: politano | U20: 30
C21: candreva | E21: 16 | G21: diawara | I21: 1 | K21: ramirez | M21: 17 | O21: ricci | Q21: 9 | S21: viola | U21: 5
C22: linetty | E22: 5 | G22: mckenny | I22: 3 | K22: miranchuk | M22: 11 | O22: marin | Q22: 3 | S22: bakayoko | U22: 9
C23: sottil | E23: 5 | G23: svanberg | I23: 1 | K23: bennacer | M23: 1 | O23: miguel veloso | Q23: 3 | S23: castillejo | U23: 3
C24: tameze | E24: 1 | F24: =SUM(E17:E24) -> 145 | G24: maxim lopez | I24: 1 | J24: =SUM(I17:I24) -> 105 | K24: bernardeschi | M24: 1 | N24: =SUM(M17:M24) -> 161 | O24: ionita | Q24: 1 | R24: =SUM(Q17:Q24) -> 128 | S24: daamsgard | U24: 1 | V24: =SUM(U17:U24) -> 139
C25: lukaku | E25: 171 | G25: ibrahimovic | I25: 150 | K25: caputo | M25: 128 | O25: rebic | Q25: 62 | S25: lautaro | U25: 110
C26: cornelius | E26: 16 | G26: osimhen | I26: 82 | K26: belotti | M26: 87 | O26: insigne l. | Q26: 46 | S26: berardi | U26: 83
B27: ATT | C27: bonazzoli | E27: 10 | G27: leao | I27: 16 | K27: delofeu | M27: 21 | O27: joao pedro | Q27: 56 | S27: lapadula | U27: 24
C28: messias | E28: 7 | G28: colombo | I28: 5 | K28: vhlaovic | M28: 5 | O28: correa | Q28: 25 | S28: pandev | U28: 5
C29: koume | E29: 22 | G29: petagna | I29: 1 | K29: palacio | M29: 6 | O29: simy | Q29: 30 | S29: sau | U29: 1
C30: galabinov | E30: 13 | F30: =SUM(E25:E30) -> 239 | G30: shomorodov | I30: 1 | J30: =SUM(I25:I30) -> 255 | K30: hauge | M30: 1 | N30: =SUM(M25:M30) -> 248 | O30: lasagna | Q30: 29 | R30: =SUM(Q25:Q30) -> 248 | S30: lammers | U30: 10 | V30: =SUM(U25:U30) -> 233
C31: TOT SPESO | E31: =SUM(E6:E30) -> 500 | G31: TOT SPESO | I31: =SUM(I6:I30) -> 498 | K31: TOT SPESO | M31: =SUM(M6:M30) -> 496 | O31: TOT SPESO | Q31: =SUM(Q6:Q30) -> 500 | S31: TOT SPESO | U31: =SUM(U6:U30) -> 453
C32: RIMANENTI | E32: =500-E31 -> 0 | G32: RIMANENTI | I32: =500-I31 -> 2 | K32: RIMANENTI | M32: =500-M31 -> 4 | O32: RIMANENTI | Q32: =500-Q31 -> 0 | S32: RIMANENTI | U32: =500-U31 -> 47
C39: PIE | G39: ISMO | K39: LOMBA | O39: NIUB | S39: SBRI
C40: GIOCATORE | E40: PREZZO | F40: TOT | G40: GIOCATORE | I40: PREZZO | J40: TOT | K40: GIOCATORE | M40: PREZZO | N40: TOT | O40: GIOCATORE | Q40: PREZZO | R40: TOT | S40: GIOCATORE | U40: PREZZO | V40: TOT
C41: szcezny | E41: 50 | G41: donnarumma | I41: 45 | K41: sportiello | M41: 5 | O41: strakosha | Q41: 29 | S41: dragowski | U41: 17
B42: POR | C42: reina | E42: 1 | G42: tatarusanu | I42: 6 | K42: cragno | M42: 13 | O42: musso | Q42: 14 | S42: audero | U42: 1
C43: buffon | E43: 7 | F43: =SUM(E41:E43) -> 58 | G43: radu | I43: 2 | J43: =SUM(I41:I43) -> 53 | K43: silvestri | M43: 8 | N43: =SUM(M41:M43) -> 26 | O43: rafael | Q43: 1 | R43: =SUM(Q41:Q43) -> 44 | S43: terracciano | U43: 1 | V43: =SUM(U41:U43) -> 19
C44: di lorenzo | E44: 18 | G44: de ligt | I44: 15 | K44: kolarov | M44: 8 | O44: chiellini | Q44: 8 | S44: bonucci | U44: 18
C45: spinazzola | E45: 14 | G45: t. hernandez | I45: 41 | K45: de vrij | M45: 29 | O45: hakimi | Q45: 39 | S45: palomino | U45: 11
C46: pellegrini lu | E46: 5 | G46: d'ambrosio | I46: 10 | K46: tomiyasu | M46: 11 | O46: koulibaly | Q46: 25 | S46: hateboer | U46: 21
B47: DIF | C47: augello | E47: 8 | G47: n'koulu | I47: 6 | K47: glik | M47: 4 | O47: rodriguez | Q47: 6 | S47: skriniar | U47: 10
C48: danilo | E48: 5 | G48: ibanez | I48: 4 | K48: kumbulla | M48: 9 | O48: kjaer | Q48: 8 | S48: piccini | U48: 1
...

Sheet ROSE 2022
H1: FANTAGHEIS 2021-2022
C4: TAFFO | G4: FORE | K4: CASSI | O4: ALFIO | S4: ALE
C5: GIOCATORE | E5: PREZZO | F5: TOT | G5: GIOCATORE | I5: PREZZO | J5: TOT | K5: GIOCATORE | M5: PREZZO | N5: TOT | O5: GIOCATORE | Q5: PREZZO | R5: TOT | S5: GIOCATORE | U5: PREZZO | V5: TOT
C6: HANDANOVIC | E6: 49 | G6: MAIGNAN | I6: 53 | K6: CONSIGLI | M6: 21 | O6: MERET | Q6: 41 | S6: RUI PATRICIO | U6: 32
B7: POR | C7: RADU I. | E7: 1 | G7: TATARUSANU | I7: 1 | K7: PERIN | M7: 8 | O7: OSPINA | Q7: 10 | S7: MONTIPO' | U7: 7
C8: CORDAZ | E8: 1 | F8: =SUM(E6:E8) -> 51 | G8: PLIZZARI | I8: 1 | J8: =SUM(I6:I8) -> 55 | K8: ZOET | M8: 2 | N8: =SUM(M6:M8) -> 31 | O8: BELEC | Q8: 1 | R8: =SUM(Q6:Q8) -> 52 | S8: FUZATO | U8: 1 | V8: =SUM(U6:U8) -> 40
C9: KJAER | E9: 30 | G9: MAEHLE | I9: 25 | K9: ACERBI | M9: 21 | O9: BIRAGHI | Q9: 12 | S9: DI LORENZO | U9: 27
C10: DE VRIJ | E10: 30 | G10: MILENKOVIC | I10: 23 | K10: DANILO | M10: 10 | O10: FARAONI | Q10: 27 | S10: BASTONI | U10: 20
C11: DE LIGT | E11: 30 | G11: TOMORI | I11: 35 | K11: CALABRIA | M11: 17 | O11: CALDARA | Q11: 1 | S11: BREMER | U11: 20
B12: DIF | C12: DUMFRIES | E12: 30 | G12: SINGO | I12: 13 | K12: MANOLAS | M12: 21 | O12: RUGGERI | Q12: 1 | S12: STRYGER LARSEN | U12: 6
C13: MARCHIZZA | E13: 1 | G13: KUMBULLA | I13: 1 | K13: BONIFAZI | M13: 4 | O13: DEMIRAL | Q13: 8 | S13: ALEX SANDRO | U13: 6
C14: DJIMSITI | E14: 8 | G14: ZAPPA | I14: 1 | K14: D'AMBROSIO | M14: 7 | O14: NASTASIC | Q14: 1 | S14: MARIO RUI | U14: 3
C15: AMIAN | E15: 1 | G15: ODRIOZOLA | I15: 7 | K15: ROMAGNOLI | M15: 3 | O15: ANSALDI | Q15: 3 | S15: COLLEY | U15: 1
C16: FARES | E16: 1 | F16: =SUM(E9:E16) -> 131 | G16: SMALLING | I16: 7 | J16: =SUM(I9:I16) -> 112 | K16: CHIELLINI | M16: 1 | N16: =SUM(M9:M16) -> 84 | O16: SAMIR | Q16: 1 | R16: =SUM(Q9:Q16) -> 54 | S16: VANHEUSDEN | U16: 1 | V16: =SUM(U9:U16) -> 84
C17: VERETOUT | E17: 66 | G17: KESSIE' | I17: 61 | K17: MKHITARYAN | M17: 70 | O17: KULUSEVSKI | Q17: 37 | S17: PELLEGRINI LO. | U17: 63
C18: LOPEZ M. | E18: 4 | G18: ZANIOLO | I18: 43 | K18: CHIESA | M18: 83 | O18: MALINOVSKYI | Q18: 60 | S18: DIAZ B. | U18: 64
C19: NANDEZ | E19: 14 | G19: SVANBERG | I19: 10 | K19: FELIPE ANDERSON | M19: 51 | O19: PEREYRA | Q19: 46 | S19: CANDREVA | U19: 25
B20: CEN | C20: DE ROON | E20: 2 | G20: TONALI | I20: 15 | K20: SAELEMAEKERS | M20: 10 | O20: MARIN | Q20: 19 | S20: ZURKOWSKI | U20: 1
C21: MIGUEL VELOSO | E21: 6 | G21: PRAET | I21: 1 | K21: LUCAS LEIVA | M21: 1 | O21: MIRANCHUK | Q21: 16 | S21: MAGGIORE | U21: 12
C22: HAAS | E22: 1 | G22: PULGAR | I22: 1 | K22: RABIOT | M22: 2 | O22: HEYMANS | Q22: 1 | S22: BAJRAMI | U22: 20
C23: PERETZ | E23: 1 | G23: TAMEZE | I23: 1 | K23: ELMAS | M23: 1 | O23: BERNARDESCHI | Q23: 1 | S23: TORREIRA | U23: 5
C24: SENSI | E24: 1 | F24: =SUM(E17:E24) -> 95 | G24: KOVALENKO | I24: 1 | J24: =SUM(I17:I24) -> 133 | K24: MESSIAS | M24: 8 | N24: =SUM(M17:M24) -> 226 | O24: RICCI S. | Q24: 1 | R24: =SUM(Q17:Q24) -> 181 | S24: SCHOUTEN | U24: 2 | V24: =SUM(U17:U24) -> 192
C25: JOAO PEDRO | E25: 87 | G25: ABRAHAM | I25: 110 | K25: ZAPATA D. | M25: 96 | O25: DYBALA | Q25: 94 | S25: MURIEL | U25: 120
C26: CAICEDO | E26: 41 | G26: IBRAHIMOVIC | I26: 66 | K26: CAPUTO | M26: 42 | O26: BERARDI | Q26: 71 | S26: GIROUD | U26: 45
B27: ATT | C27: BELOTTI | E27: 75 | G27: KEAN | I27: 8 | K27: DEULOFEU | M27: 5 | O27: FORTE | Q27: 3 | S27: SIMEONE | U27: 5
C28: SCAMACCA | E28: 15 | G28: CUTRONE | I28: 13 | K28: SHOMURODOV | M28: 6 | O28: PUSSETTO | Q28: 10 | S28: GYASI | U28: 1
C29: VERDE | E29: 2 | G29: DI FRANCESCO F. | I29: 1 | K29: GABBIADINI | M29: 1 | O29: PAVOLETTI | Q29: 13 | S29: PANDEV | U29: 3
C30: HENRY | E30: 3 | F30: =SUM(E25:E30) -> 223 | G30: MAYORAL | I30: 1 | J30: =SUM(I25:I30) -> 199 | K30: PJACA | M30: 6 | N30: =SUM(M25:M30) -> 156 | O30: LASAGNA | Q30: 3 | R30: =SUM(Q25:Q30) -> 194 | S30: CANCELLIERI | U30: 1 | V30: =SUM(U25:U30) -> 175
C31: TOT SPESO | E31: =SUM(E6:E30) -> 500 | G31: TOT SPESO | I31: =SUM(I6:I30) -> 499 | K31: TOT SPESO | M31: =SUM(M6:M30) -> 497 | O31: TOT SPESO | Q31: =SUM(Q6:Q30) -> 481 | S31: TOT SPESO | U31: =SUM(U6:U30) -> 491
C32: RIMANENTI | E32: =500-E31 -> 0 | G32: RIMANENTI | I32: =500-I31 -> 1 | K32: RIMANENTI | M32: =500-M31 -> 3 | O32: RIMANENTI | Q32: =500-Q31 -> 19 | S32: RIMANENTI | U32: =500-U31 -> 9
C39: PIE | G39: ISMO | K39: LOMBA | O39: NIUB | S39: SBRI
C40: GIOCATORE | E40: PREZZO | F40: TOT | G40: GIOCATORE | I40: PREZZO | J40: TOT | K40: GIOCATORE | M40: PREZZO | N40: TOT | O40: GIOCATORE | Q40: PREZZO | R40: TOT | S40: GIOCATORE | U40: PREZZO | V40: TOT
C41: MUSSO | E41: 34 | G41: AUDERO | I41: 9 | K41: SZCZESNY | M41: 47 | O41: MILINKOVIC-SAVIC V. | Q41: 6 | S41: REINA | U41: 40
B42: POR | C42: SPORTIELLO | E42: 1 | G42: CRAGNO | I42: 17 | K42: SKORUPSKI | M42: 4 | O42: DRAGOWSKI | Q42: 12 | S42: LEZZERINI | U42: 1
C43: VICARIO | E43: 2 | F43: =SUM(E41:E43) -> 37 | G43: SIRIGU | I43: 3 | J43: =SUM(I41:I43) -> 29 | K43: PINSOGLIO | M43: 1 | N43: =SUM(M41:M43) -> 52 | O43: SILVESTRI | Q43: 12 | R43: =SUM(Q41:Q43) -> 30 | S43: STRAKOSHA | U43: 1 | V43: =SUM(U41:U43) -> 42
C44: BONUCCI | E44: 20 | G44: GOSENS | I44: 60 | K44: LAZZARI | M44: 22 | O44: MOLINA N. | Q44: 19 | S44: DALBERT | U44: 4
C45: LUIZ FELIPE | E45: 6 | G45: HERNANDEZ T. | I45: 58 | K45: CRISCITO | M45: 17 | O45: CUADRADO | Q45: 42 | S45: HYSAJ | U45: 8
C46: LYKOGIANNIS | E46: 2 | G46: MANCINI | I46: 28 | K46: STOJANOVIC | M46: 1 | O46: KARSDORP | Q46: 17 | S46: SKRINIAR | U46: 40
B47: DIF | C47: BASTONI S. | E47: 7 | G47: NUYTINCK | I47: 15 | K47: VINA | M47: 21 | O47: FERRARI G. | Q47: 8 | S47: BERESZYNSKI | U47: 1
C48: AUGELLO | E48: 8 | G48: UDOGIE | I48: 1 | K48: DARMIAN | M48: 5 | O48: ZAPPACOSTA | Q48: 12 | S48: KOULIBALY | U48: 22
...

Sheet ROSE 2023
H1: FANTAGHEIS 2022-2023
C4: TAFFO GAY | G4: FOR(R)EST | K4: CASSI NO BARNEY | O4: ALFIO DUE GAY | S4: ALè Alè | X4: WINNER FUSTO
C5: GIOCATORE | E5: PREZZO | F5: TOT | G5: GIOCATORE | I5: PREZZO | J5: TOT | K5: GIOCATORE | M5: PREZZO | N5: TOT | O5: Di Lorenzo | Q5: PREZZO | R5: TOT | S5: GIOCATORE | U5: PREZZO | V5: TOT | X5: TAFFO
C6: Szczesny | E6: 55 | G6: Maignan | I6: 68 | K6: Rui Patricio | M6: 50 | O6: Meret | Q6: 56 | S6: Musso | U6: 51
B7: POR | C7: Perin | E7: 6 | G7: Tatarusanu | I7: 1 | K7: Svilar | M7: 1 | O7: Sirigu | Q7: 1 | S7: Sportiello | U7: 1
C8: Pinsoglio | E8: 1 | F8: =SUM(E6:E8) -> 62 | G8: Sepe | I8: 1 | J8: =SUM(I6:I8) -> 70 | K8: Terracciano | M8: 1 | N8: =SUM(M6:M8) -> 52 | O8: Falcone | Q8: 1 | R8: =SUM(Q6:Q8) -> 58 | S8: Rossi F. | U8: 1 | V8: =SUM(U6:U8) -> 53
C9: Bremer | E9: 30 | G9: Hernandez T. | I9: 49 | K9: Calabria | M9: 19 | O9: Di Lorenzo | Q9: 29 | S9: Dodo' | U9: 15
C10: Tomori | E10: 26 | G10: Maehle | I10: 11 | K10: Gosens | M10: 14 | O10: Biraghi | Q10: 20 | S10: Rrahmani | U10: 23
C11: Karsdorp | E11: 2 | G11: Kalulu | I11: 14 | K11: Dest | M11: 4 | O11: Faraoni | Q11: 22 | S11: Skriniar | U11: 24
B12: DIF | C12: Singo | E12: 15 | G12: De Silvestri | I12: 6 | K12: Lazzari | M12: 15 | O12: Ghiglione | Q12: 4 | S12: Fazio | U12: 1
C13: Igor | E13: 1 | G13: Lucumi' | I13: 1 | K13: Ferrari G. | M13: 3 | O13: Vojvoda | Q13: 8 | S13: Danilo | U13: 15
C14: Dimarco | E14: 8 | G14: Kjaer | I14: 3 | K14: Celik | M14: 2 | O14: Umtiti | Q14: 1 | S14: Mancini | U14: 8
C15: Soppy | E15: 5 | G15: Zortea | I15: 1 | K15: Augello | M15: 2 | O15: Patric | Q15: 1 | S15: Reca | U15: 1
C16: Gatti | E16: 1 | F16: =SUM(E9:E16) -> 88 | G16: Izzo | I16: 1 | J16: =SUM(I9:I16) -> 86 | K16: Alex sandro | M16: 1 | N16: =SUM(M9:M16) -> 60 | O16: Bereszynski | Q16: 1 | R16: =SUM(Q9:Q16) -> 86 | S16: Kasius | U16: 1 | V16: =SUM(U9:U16) -> 88
C17: Zaniolo | E17: 33 | G17: Zielinski | I17: 64 | K17: Kvaratskhelia | M17: 70 | O17: Gyasi | Q17: 15 | S17: Milinkovic-Savic | U17: 70
C18: Felipe Anderson | E18: 36 | G18: Tonali | I18: 28 | K18: Zaccagni | M18: 32 | O18: Miranchuk | Q18: 8 | S18: Candreva | U18: 17
C19: Frattesi | E19: 12 | G19: Vecino | I19: 4 | K19: Traore' Hj. | M19: 10 | O19: Pogba | Q19: 30 | S19: Bennacer | U19: 7
B20: CEN | C20: Pereyra | E20: 29 | G20: Mkhitaryan | I20: 5 | K20: De Roon | M20: 2 | O20: Messias | Q20: 5 | S20: Kostic | U20: 6
C21: Lopez M. | E21: 2 | G21: Rabiot | I21: 5 | K21: Ederson D.s. | M21: 4 | O21: Sottil | Q21: 13 | S21: Lazovic | U21: 3
C22: Sabiri | E22: 7 | G22: Sensi | I22: 3 | K22: Samardzic | M22: 1 | O22: Ikone' | Q22: 3 | S22: Amrabat | U22: 6
C23: Zalewski | E23: 1 | G23: Miretti | I23: 1 | K23: Soriano | M23: 2 | O23: Cristante | Q23: 2 | S23: Ricci S. | U23: 1
C24: Valoti | E24: 1 | F24: =SUM(E17:E24) -> 121 | G24: Pobega | I24: 1 | J24: =SUM(I17:I24) -> 111 | K24: Agudelo | M24: 1 | N24: =SUM(M17:M24) -> 122 | O24: Lovric | Q24: 3 | R24: =SUM(Q17:Q24) -> 79 | S24: Saelemaekers | U24: 1 | V24: =SUM(U17:U24) -> 111
C25: Henry | E25: 48 | G25: Abraham | I25: 177 | K25: Immobile | M25: 210 | O25: Dybala | Q25: 102 | S25: Arnautovic | U25: 111
C26: Osimhen | E26: 120 | G26: Quagliarella | I26: 1 | K26: Ceesay | M26: 16 | O26: Muriel | Q26: 46 | S26: Raspadori | U26: 12
B27: ATT | C27: Beto | E27: 57 | G27: Sanabria | I27: 35 | K27: Dessers | M27: 14 | O27: Pinamonti | Q27: 58 | S27: Zapata D. | U27: 85
C28: Mota | E28: 1 | G28: Hojlund | I28: 14 | K28: Gonzalez N. | M28: 15 | O28: Origi | Q28: 14 | S28: Okereke | U28: 20
C29: Destro | E29: 2 | G29: Colombo | I29: 1 | K29: Rebic | M29: 9 | O29: Dzeko | Q29: 29 | S29: Pedro | U29: 18
C30: Verde | E30: 1 | F30: =SUM(E25:E30) -> 229 | G30: Belotti | I30: 3 | J30: =SUM(I25:I30) -> 231 | K30: Cabral | M30: 1 | N30: =SUM(M25:M30) -> 265 | O30: Lozano | Q30: 23 | R30: =SUM(Q25:Q30) -> 272 | S30: Pellegri | U30: 1 | V30: =SUM(U25:U30) -> 247
C31: TOT SPESO | E31: =SUM(E6:E30) -> 500 | G31: TOT SPESO | I31: =SUM(I6:I30) -> 498 | K31: TOT SPESO | M31: =SUM(M6:M30) -> 499 | O31: TOT SPESO | Q31: =SUM(Q6:Q30) -> 495 | S31: TOT SPESO | U31: =SUM(U6:U30) -> 499
C32: RIMANENTI | E32: =500-E31 -> 0 | G32: RIMANENTI | I32: =500-I31 -> 2 | K32: RIMANENTI | M32: =500-M31 -> 1 | O32: RIMANENTI | Q32: =500-Q31 -> 5 | S32: RIMANENTI | U32: =500-U31 -> 1
C39: PIE TRO IA | G39: ISN'T MO | K39: LOMBA LGIA | O39: NEWB | S39: SBRI CIOLO
C40: GIOCATORE | E40: PREZZO | F40: TOT | G40: GIOCATORE | I40: PREZZO | J40: TOT | K40: GIOCATORE | M40: PREZZO | N40: TOT | O40: GIOCATORE | Q40: PREZZO | R40: TOT | S40: GIOCATORE | U40: PREZZO | V40: TOT
C41: Handanovic | E41: 46 | G41: Provedel | I41: 18 | K41: Silvestri | M41: 15 | O41: Gollini | Q41: 33 | S41: Milinkovic-Savic V. | U41: 11
B42: POR | C42: Onana | E42: 15 | G42: Skorupski | I42: 3 | K42: Montipo' | M42: 5 | O42: Vicario | Q42: 1 | S42: Audero | U42: 8
C43: Berisha | E43: 1 | F43: =SUM(E41:E43) -> 62 | G43: Luis Maximiano | I43: 2 | J43: =SUM(I41:I43) -> 23 | K43: Consigli | M43: 10 | N43: =SUM(M41:M43) -> 30 | O43: Dragowski | Q43: 2 | R43: =SUM(Q41:Q43) -> 36 | S43: Contini | U43: 1 | V43: =SUM(U41:U43) -> 20
C44: Udogie | E44: 27 | G44: Bonucci | I44: 15 | K44: Smalling | M44: 19 | O44: Dumfries | Q44: 30 | S44: Spinazzola | U44: 21
C45: Mazzocchi | E45: 6 | G45: Rodrigo Becao | I45: 8 | K45: Romagnoli | M45: 10 | O45: Ibanez | Q45: 9 | S45: Kim | U45: 21
C46: Bastoni S. | E46: 29 | G46: Kyriakopoulos | I46: 8 | K46: Bastoni | M46: 10 | O46: De Vrij | Q46: 9 | S46: Milenkovic | U46: 7
B47: DIF | C47: Zappacosta | E47: 7 | G47: Valeri | I47: 2 | K47: Cambiaso | M47: 4 | O47: Parisi | Q47: 7 | S47: Hateboer | U47: 3
C48: Darmian | E48: 2 | G48: Okoli | I48: 1 | K48: Demiral | M48: 6 | O48: Lykogiannis | Q48: 1 | S48: Marusic | U48: 1
...

Sheet ROSE 2024
H1: FANTAGHEIS 2023-24
C4: TAFFO | G4: FOR(R)EST | K4: BARNEY | O4: ALFIO DUE GAY | S4: ALè Alè | X4: WINNER
C5: GIOCATORE | E5: PREZZO | F5: TOT | G5: GIOCATORE | I5: PREZZO | J5: TOT | K5: GIOCATORE | M5: PREZZO | N5: TOT | O5: GIOCATORE | Q5: PREZZO | R5: TOT | S5: GIOCATORE | U5: PREZZO | V5: TOT | X5: TAFFO
C6: Milinkovic-Savic V. | E6: 16 | G6: Maignan | I6: 52 | K6: Skorupski | M6: 26 | O6: Musso | Q6: 21 | S6: Rui Patricio | U6: 40
B7: POR | C7: Turati | E7: 1 | G7: Sportiello | I7: 1 | K7: Silvestri | M7: 16 | O7: Carnesecchi | Q7: 4 | S7: Svilar | U7: 1
C8: Christensen O. | E8: 1 | F8: =SUM(E6:E8) -> 18 | G8: Martinez Jo. | I8: 1 | J8: =SUM(I6:I8) -> 54 | K8: Radunovic | M8: 1 | N8: =SUM(M6:M8) -> 43 | O8: Falcone | Q8: 18 | R8: =SUM(Q6:Q8) -> 43 | S8: Boer | U8: 1 | V8: =SUM(U6:U8) -> 42
C9: Di Lorenzo | E9: 40 | G9: Tomori | I9: 17 | K9: Calabria | M9: 11 | O9: Dimarco | Q9: 48 | S9: Darmian | U9: 9
C10: Bremer | E10: 25 | G10: Danilo | I10: 27 | K10: Pavard | M10: 16 | O10: Parisi | Q10: 6 | S10: Bastoni | U10: 21
C11: Zappacosta | E11: 16 | G11: Spinazzola | I11: 16 | K11: Casale | M11: 8 | O11: Rodriguez R. | Q11: 7 | S11: Scalvini | U11: 8
B12: DIF | C12: Milenkovic | E12: 4 | G12: Buongiorno | I12: 16 | K12: Kolasinac | M12: 10 | O12: Romagnoli | Q12: 12 | S12: Lucumi' | U12: 3
C13: Monterisi | E13: 1 | G13: Kyriakopoulos | I13: 3 | K13: Kristensen | M13: 15 | O13: Ebuehi | Q13: 5 | S13: Romagnoli S. | U13: 1
C14: Ebosele | E14: 1 | G14: Natan | I14: 5 | K14: Mari' | M14: 1 | O14: Ruggeri | Q14: 1 | S14: Dodo' | U14: 2
C15: Zortea | E15: 1 | G15: Kalulu | I15: 2 | K15: Toloi | M15: 2 | O15: Birindelli | Q15: 5 | S15: De Vrij | U15: 2
C16: Caldirola | E16: 1 | F16: =SUM(E9:E16) -> 89 | G16: Toljan | I16: 1 | J16: =SUM(I9:I16) -> 87 | K16: Kristiansen | M16: 1 | N16: =SUM(M9:M16) -> 64 | O16: Sabelli | Q16: 1 | R16: =SUM(Q9:Q16) -> 85 | S16: Kamara H. | U16: 1 | V16: =SUM(U9:U16) -> 47
C17: Calhanoglu | E17: 36 | G17: Rabiot | I17: 44 | K17: Koopmeiners | M17: 37 | O17: Zaccagni | Q17: 52 | S17: Chukwueze | U17: 20
C18: Lindstrom | E18: 7 | G18: Samardzic | I18: 29 | K18: Zielinski | M18: 29 | O18: Pulisic | Q18: 49 | S18: Ferguson | U18: 28
C19: Ederson D.s. | E19: 6 | G19: Radonjic | I19: 22 | K19: Mkhitaryan | M19: 14 | O19: Ilic | Q19: 5 | S19: Colpani | U19: 23
B20: CEN | C20: Cristante | E20: 5 | G20: Loftus-Cheek | I20: 21 | K20: Aouar | M20: 1 | O20: Oudin | Q20: 1 | S20: Ricci S. | U20: 10
C21: Kastanos | E21: 1 | G21: Musah | I21: 3 | K21: Guendouzi | M21: 4 | O21: Mazzitelli | Q21: 1 | S21: Lazovic | U21: 6
C22: Messias | E22: 1 | G22: Fagioli | I22: 1 | K22: Gagliardini | M22: 5 | O22: Bajrami | Q22: 2 | S22: Lovric | U22: 10
C23: Paredes | E23: 1 | G23: Arthur Melo | I23: 1 | K23: Folorunsho | M23: 3 | O23: Freuler | Q23: 1 | S23: Krunic | U23: 1
C24: Ramadani | E24: 1 | F24: =SUM(E17:E24) -> 58 | G24: Harroui | I24: 1 | J24: =SUM(I17:I24) -> 122 | K24: Baldanzi | M24: 4 | N24: =SUM(M17:M24) -> 97 | O24: Renato Sanches | Q24: 1 | R24: =SUM(Q17:Q24) -> 112 | S24: Rafia | U24: 4 | V24: =SUM(U17:U24) -> 102
C25: Martinez L. | E25: 212 | G25: Giroud | I25: 126 | K25: Berardi | M25: 116 | O25: Vlahovic | Q25: 210 | S25: Lukaku | U25: 190
C26: Zirkzee | E26: 60 | G26: Pinamonti | I26: 33 | K26: Chiesa | M26: 123 | O26: Arnautovic | Q26: 4 | S26: Lauriente' | U26: 54
B27: ATT | C27: Retegui | E27: 57 | G27: Gonzalez N. | I27: 47 | K27: Ngonge | M27: 29 | O27: Kouame' | Q27: 10 | S27: Krstovic | U27: 42
C28: Caso | E28: 1 | G28: Jovic | I28: 1 | K28: Karlsson | M28: 18 | O28: Almqvist | Q28: 15 | S28: Castellanos | U28: 3
C29: Sanchez | E29: 1 | G29: Colombo | I29: 27 | K29: Thauvin | M29: 4 | O29: Djuric | Q29: 1 | S29: Petagna | U29: 14
C30: Isaksen | E30: 1 | F30: =SUM(E25:E30) -> 332 | G30: Okafor | I30: 1 | J30: =SUM(I25:I30) -> 235 | K30: Soule' | M30: 3 | N30: =SUM(M25:M30) -> 293 | O30: Deulofeu | Q30: 1 | R30: =SUM(Q25:Q30) -> 241 | S30: Mota | U30: 1 | V30: =SUM(U25:U30) -> 304
C31: TOT SPESO | E31: =SUM(E6:E30) -> 497 | G31: TOT SPESO | I31: =SUM(I6:I30) -> 498 | K31: TOT SPESO | M31: =SUM(M6:M30) -> 497 | O31: TOT SPESO | Q31: =SUM(Q6:Q30) -> 481 | S31: TOT SPESO | U31: =SUM(U6:U30) -> 495
C32: RIMANENTI | E32: =500-E31 -> 3 | G32: RIMANENTI | I32: =500-I31 -> 2 | K32: RIMANENTI | M32: =500-M31 -> 3 | O32: RIMANENTI | Q32: =500-Q31 -> 19 | S32: RIMANENTI | U32: =500-U31 -> 5
C39: PIE TRO IA | G39: ISN'T MO IMBROGLIA | K39: LOMBA LGIA | O39: NEWB | S39: FUSTO
C40: GIOCATORE | E40: PREZZO | F40: TOT | G40: GIOCATORE | I40: PREZZO | J40: TOT | K40: GIOCATORE | M40: PREZZO | N40: TOT | O40: GIOCATORE | Q40: PREZZO | R40: TOT | S40: GIOCATORE | U40: PREZZO | V40: TOT
C41: Szczesny | E41: 55 | G41: Provedel | I41: 51 | K41: Sommer | M41: 60 | O41: Di Gregorio | Q41: 13 | S41: Meret | U41: 47
B42: POR | C42: Perin | E42: 5 | G42: Sepe | I42: 1 | K42: Audero | M42: 1 | O42: Terracciano | Q42: 1 | S42: Gollini | U42: 1
C43: Pinsoglio | E43: 1 | F43: =SUM(E41:E43) -> 61 | G43: Mandas | I43: 1 | J43: =SUM(I41:I43) -> 53 | K43: Di Gennaro | M43: 1 | N43: =SUM(M41:M43) -> 62 | O43: Montipo' | Q43: 8 | R43: =SUM(Q41:Q43) -> 22 | S43: Ochoa | U43: 1 | V43: =SUM(U41:U43) -> 49
C44: Dumfries | E44: 27 | G44: Hernandez T. | I44: 42 | K44: Rrahmani | M44: 24 | O44: Posch | Q44: 18 | S44: Schuurs | U44: 17
C45: Doig | E45: 9 | G45: Acerbi | I45: 9 | K45: Carlos Augusto | M45: 11 | O45: Biraghi | Q45: 31 | S45: Baschirotto | U45: 10
C46: Bellanova | E46: 13 | G46: Bijol | I46: 4 | K46: Thiaw | M46: 7 | O46: Faraoni | Q46: 6 | S46: Mazzocchi | U46: 7
B47: DIF | C47: Beukema | E47: 3 | G47: N'dicka | I47: 10 | K47: Perez N. | M47: 7 | O47: Dragusin | Q47: 7 | S47: Martin | U47: 3
C48: Gendrey | E48: 6 | G48: Llorente D. | I48: 5 | K48: Mancini | M48: 4 | O48: Smalling | Q48: 16 | S48: Vojvoda | U48: 9
...

Sheet ROSE 2025
A1: 2026 | H1: FANTAGHEIS 2024-25
C4: TAFFO | G4: FOR(R)EST | K4: BAR NEI | O4: ALFIO DUE GAY | S4: ALè Alè
C5: GIOCATORE | E5: PREZZO | F5: TOT | G5: GIOCATORE | I5: PREZZO | J5: TOT | K5: GIOCATORE | M5: PREZZO | N5: TOT | O5: GIOCATORE | Q5: PREZZO | R5: TOT | S5: GIOCATORE | U5: PREZZO | V5: TOT
C6: Meret | E6: 42 | G6: Di Gregorio | I6: 60 | K6: Milinkovic-Savic V. | M6: 23 | O6: Skorupski | Q6: 6 | S6: Maignan | U6: 41
B7: POR | C7: Caprile | E7: 1 | G7: Perin | I7: 3 | K7: Suzuki | M7: 4 | O7: Falcone | Q7: 5 | S7: Sportiello | U7: 1
C8: Joronen | E8: 1 | F8: =SUM(E6:E8) -> 44 | G8: Okoye | I8: 7 | J8: =SUM(I6:I8) -> 70 | K8: Turati | M8: 1 | N8: =SUM(M6:M8) -> 28 | O8: Ravaglia F. | Q8: 1 | R8: =SUM(Q6:Q8) -> 12 | S8: Vasquez D. | U8: 1 | V8: =SUM(U6:U8) -> 43
C9: Dumfries | E9: 16 | G9: Buongiorno | I9: 39 | K9: Tomori | M9: 12 | O9: Hernandez T. | Q9: 56 | S9: Mancini | U9: 18
C10: Pavard | E10: 27 | G10: Cambiaso | I10: 39 | K10: Rrahmani | M10: 19 | O10: Bellanova | Q10: 38 | S10: Martinez Quarta | U10: 16
C11: Pavlovic | E11: 26 | G11: Lazzari | I11: 10 | K11: Romagnoli | M11: 5 | O11: Bijol | Q11: 12 | S11: Darmian | U11: 21
B12: DIF | C12: Martin | E12: 6 | G12: Biraghi | I12: 17 | K12: Valeri | M12: 3 | O12: Dodo' | Q12: 16 | S12: Luperto | U12: 12
C13: Dossena | E13: 1 | G13: Hermoso | I13: 3 | K13: Sosa B. | M13: 8 | O13: Delprato | Q13: 4 | S13: Cabal | U13: 5
C14: Coulibaly W. | E14: 3 | G14: Candela | I14: 1 | K14: Hummels | M14: 3 | O14: Miranda J. | Q14: 4 | S14: Masina | U14: 1
C15: Bisseck | E15: 3 | G15: Augello | I15: 1 | K15: Mari' | M15: 1 | O15: Hien | Q15: 1 | S15: Savona | U15: 3
C16: Zampano | E16: 1 | F16: =SUM(E9:E16) -> 83 | G16: Lazaro | I16: 1 | J16: =SUM(I9:I16) -> 111 | K16: De Vrij | M16: 1 | N16: =SUM(M9:M16) -> 52 | O16: Beukema | Q16: 1 | R16: =SUM(Q9:Q16) -> 132 | S16: Ehizibue | U16: 1 | V16: =SUM(U9:U16) -> 77
C17: Pasalic | E17: 24 | G17: Pellegrini Lo. | I17: 31 | K17: Orsolini | M17: 58 | O17: Colpani | Q17: 40 | S17: Maldini | U17: 28
C18: Pulisic | E18: 62 | G18: Reijnders | I18: 11 | K18: Neres | M18: 47 | O18: Chukwueze | Q18: 13 | S18: Koopmeiners | U18: 51
C19: Fabbian | E19: 19 | G19: Loftus-Cheek | I19: 24 | K19: Oristanio | M19: 18 | O19: Fazzini | Q19: 9 | S19: Brescianini | U19: 19
B20: CEN | C20: Sohm | E20: 4 | G20: Freuler | I20: 1 | K20: Guendouzi | M20: 1 | O20: Ederson D.s. | Q20: 19 | S20: Bernabe' | U20: 26
C21: Tete Morente | E21: 1 | G21: Zaniolo | I21: 7 | K21: Gyasi | M21: 4 | O21: Busio | Q21: 3 | S21: Locatelli | U21: 1
C22: Kone' M. | E22: 1 | G22: Frendrup | I22: 6 | K22: Marchwinski | M22: 4 | O22: Tchaouna | Q22: 3 | S22: Duncan | U22: 1
C23: Badelj | E23: 1 | G23: Aebischer | I23: 1 | K23: De Roon | M23: 1 | O23: Marin | Q23: 3 | S23: Paz N. | U23: 5
C24: Saelemaekers | E24: 1 | F24: =SUM(E17:E24) -> 113 | G24: Messias | I24: 5 | J24: =SUM(I17:I24) -> 86 | K24: Adli | M24: 1 | N24: =SUM(M17:M24) -> 134 | O24: Felici | Q24: 1 | R24: =SUM(Q17:Q24) -> 91 | S24: Oudin | U24: 1 | V24: =SUM(U17:U24) -> 132
C25: Lukaku | E25: 172 | G25: Dybala | I25: 101 | K25: Leao | M25: 112 | O25: Kvaratskhelia | Q25: 151 | S25: Dovbyk | U25: 143
C26: Gudmundsson A. | E26: 32 | G26: Pinamonti | I26: 62 | K26: Thuram | M26: 160 | O26: Yildiz | Q26: 87 | S26: De Ketelaere | U26: 45
B27: ATT | C27: Taremi | E27: 43 | G27: Kean | I27: 33 | K27: Luvumbo | M27: 10 | O27: Noslin | Q27: 7 | S27: Krstovic | U27: 54
C28: Piccoli | E28: 5 | G28: Adams C. | I28: 35 | K28: Mihaila | M28: 1 | O28: Esposito Se. | Q28: 8 | S28: Caprari | U28: 1
C29: Raspadori | E29: 2 | G29: Sanabria | I29: 1 | K29: Rebic | M29: 1 | O29: Beltran L. | Q29: 1 | S29: Milik | U29: 4
C30: Benedyczak | E30: 1 | F30: =SUM(E25:E30) -> 255 | G30: Mota | I30: 1 | J30: =SUM(I25:I30) -> 233 | K30: Mbangula | M30: 2 | N30: =SUM(M25:M30) -> 286 | O30: Sanchez | Q30: 1 | R30: =SUM(Q25:Q30) -> 255 | S30: Isaksen | U30: 1 | V30: =SUM(U25:U30) -> 248
C31: TOT SPESO | E31: =SUM(E6:E30) -> 495 | G31: TOT SPESO | I31: =SUM(I6:I30) -> 500 | K31: TOT SPESO | M31: =SUM(M6:M30) -> 500 | O31: TOT SPESO | Q31: =SUM(Q6:Q30) -> 490 | S31: TOT SPESO | U31: =SUM(U6:U30) -> 500
C32: RIMANENTI | E32: =500-E31 -> 5 | G32: RIMANENTI | I32: =500-I31 -> 0 | K32: RIMANENTI | M32: =500-M31 -> 0 | O32: RIMANENTI | Q32: =500-Q31 -> 10 | S32: RIMANENTI | U32: =500-U31 -> 0
C39: CARL | G39: ISN'T MO IMBROGLIA | K39: LOMBA LGIA | O39: NEWB | S39: FUSTOLOTTI | X39: WINNER
C40: GIOCATORE | E40: PREZZO | F40: TOT | G40: GIOCATORE | I40: PREZZO | J40: TOT | K40: GIOCATORE | M40: PREZZO | N40: TOT | O40: GIOCATORE | Q40: PREZZO | R40: TOT | S40: GIOCATORE | U40: PREZZO | V40: TOT | X40: FUSTO
C41: Carnesecchi | E41: 33 | G41: Svilar | I41: 48 | K41: Sommer | M41: 61 | O41: De Gea | Q41: 11 | S41: Provedel | U41: 41
B42: POR | C42: Rui Patricio | E42: 1 | G42: Ryan | I42: 1 | K42: Martinez Jo. | M42: 1 | O42: Terracciano | Q42: 4 | S42: Mandas | U42: 1
C43: Montipo' | E43: 6 | F43: =SUM(E41:E43) -> 40 | G43: Reina | I43: 1 | J43: =SUM(I41:I43) -> 50 | K43: Di Gennaro | M43: 1 | N43: =SUM(M41:M43) -> 63 | O43: Audero | Q43: 1 | R43: =SUM(Q41:Q43) -> 16 | S43: Gollini | U43: 4 | V43: =SUM(U41:U43) -> 46
C44: Bremer | E44: 40 | G44: Dimarco | I44: 55 | K44: Gosens | M44: 22 | O44: Di Lorenzo | Q44: 35 | S44: Bastoni | U44: 26
C45: Ruggeri | E45: 30 | G45: Kossounou | I45: 7 | K45: Acerbi | M45: 12 | O45: Palomino | Q45: 1 | S45: Gatti | U45: 17
C46: Zappacosta | E46: 9 | G46: Coco | I46: 16 | K46: Emerson Royal | M46: 6 | O46: Spinazzola | Q46: 18 | S46: Zortea | U46: 16
B47: DIF | C47: Angelino | E47: 9 | G47: Dorgu | I47: 12 | K47: Sabelli | M47: 4 | O47: Carlos Augusto | Q47: 10 | S47: Danilo | U47: 6
C48: Viti | E48: 1 | G48: Tchatchoua | I48: 12 | K48: N'Dicka | M48: 5 | O48: Mina | Q48: 5 | S48: Kyriakopoulos | U48: 5
...

Sheet ROSE 2026
H1: FANTAGHEIS 2025-26
C4: TAFFO | G4: FOR(R)EST | K4: BAR NEI | O4: ALFIO DUE GAY | S4: ALè Alè
C5: GIOCATORE | E5: PREZZO | F5: TOT | G5: GIOCATORE | I5: PREZZO | J5: TOT | K5: GIOCATORE | M5: PREZZO | N5: TOT | O5: GIOCATORE | Q5: PREZZO | R5: TOT | S5: GIOCATORE | U5: PREZZO | V5: TOT
C6: Carnesecchi | E6: 40 | G6: Meret | I6: 44 | K6: Leali | M6: 8 | O6: Provedel | Q6: 17 | S6: Svilar | U6: 52
B7: POR | C7: Sportiello | E7: 1 | G7: Audero | I7: 2 | K7: Semper | M7: 2 | O7: Mandas | Q7: 2 | S7: Vasquez D. | U7: 1
C8: Okoye | E8: 1 | F8: =SUM(E6:E8) -> 42 | G8: Montipò | I8: 1 | J8: =SUM(I6:I8) -> 47 | K8: Suzuki | M8: 13 | N8: =SUM(M6:M8) -> 23 | O8: Falcone | Q8: 13 | R8: =SUM(Q6:Q8) -> 32 | S8: Gollini | U8: 1 | V8: =SUM(U6:U8) -> 54
C9: Bastoni | E9: 35 | G9: Gosens | I9: 40 | K9: Gila | M9: 8 | O9: Buongiorno | Q9: 27 | S9: Estupinan | U9: 9
C10: Miranda J. | E10: 16 | G10: Bellanova | I10: 35 | K10: Tomori | M10: 5 | O10: Dodò | Q10: 30 | S10: N'Dicka | U10: 15
C11: Solet | E11: 25 | G11: De Winter | I11: 3 | K11: Gatti | M11: 7 | O11: Rrahmani | Q11: 21 | S11: Baschirotto | U11: 10
B12: DIF | C12: Vasquez | E12: 12 | G12: Delprato | I12: 13 | K12: Palestra | M12: 5 | O12: Tavares N. | Q12: 24 | S12: Vojvoda | U12: 9
C13: Gabbia | E13: 4 | G13: Comuzzo | I13: 4 | K13: De Vrij | M13: 2 | O13: Canestrelli | Q13: 4 | S13: Ramon | U13: 15
C14: Gallo | E14: 5 | G14: Ranieri L. | I14: 4 | K14: Pezzella Giu. | M14: 1 | O14: Kossounou | Q14: 1 | S14: Mina | U14: 4
C15: Ismajli | E15: 2 | G15: Kristensen T. | I15: 1 | K15: Doig | M15: 4 | O15: Frese | Q15: 1 | S15: Gaspar K. | U15: 3
C16: Kelly L. | E16: 1 | F16: =SUM(E9:E16) -> 100 | G16: Ahanor | I16: 1 | J16: =SUM(I9:I16) -> 101 | K16: Hermoso | M16: 2 | N16: =SUM(M9:M16) -> 34 | O16: Djimsiti | Q16: 1 | R16: =SUM(Q9:Q16) -> 109 | S16: Heggem | U16: 1 | V16: =SUM(U9:U16) -> 66
C17: Conceicao | E17: 36 | G17: Orsolini | I17: 70 | K17: Zaccagni | M17: 80 | O17: Pulisic | Q17: 76 | S17: Modric | U17: 30
C18: Rabiot | E18: 35 | G18: Zambo Anguissa | I18: 23 | K18: Zhegrova | M18: 21 | O18: Gudmundsson A. | Q18: 85 | S18: Thuram K. | U18: 30
C19: Bernabè | E19: 20 | G19: Loftus-Cheek | I19: 21 | K19: Odgaard | M19: 33 | O19: Tramoni M. | Q19: 26 | S19: Saelemaekers | U19: 22
B20: CEN | C20: Sucic P. | E20: 13 | G20: Rowe | I20: 16 | K20: Lobotka | M20: 3 | O20: Oristanio | Q20: 19 | S20: Zerbin | U20: 5
C21: Pasalic | E21: 12 | G21: Da Cunha | I21: 7 | K21: Stanciu | M21: 4 | O21: Baturina | Q21: 3 | S21: Gaetano | U21: 2
C22: Bernardeschi | E22: 1 | G22: Jashari | I22: 1 | K22: Thorstvedt | M22: 1 | O22: Gronbaek | Q22: 2 | S22: Ekkelenkamp | U22: 1
C23: Frendrup | E23: 1 | G23: Cristante | I23: 1 | K23: Zaniolo | M23: 6 | O23: Fadera | Q23: 1 | S23: El Shaarawy | U23: 1
C24: Mkhitaryan | E24: 1 | F24: =SUM(E17:E24) -> 119 | G24: Fofana Y. | I24: 1 | J24: =SUM(I17:I24) -> 140 | K24: Maldini | M24: 7 | N24: =SUM(M17:M24) -> 155 | O24: Fazzini | Q24: 3 | R24: =SUM(Q17:Q24) -> 215 | S24: El Aynaoui | U24: 1 | V24: =SUM(U17:U24) -> 92
C25: Kean | E25: 160 | G25: Hojlund | I25: 108 | K25: Castro S. | M25: 71 | O25: Castellanos | Q25: 101 | S25: Yildiz | U25: 116
C26: Zapata D. | E26: 15 | G26: Dybala | I26: 51 | K26: Leao | M26: 135 | O26: Dia | Q26: 11 | S26: Soulè | U26: 130
B27: ATT | C27: Vlahovic | E27: 40 | G27: Lucca | I27: 15 | K27: De Ketelaere | M27: 30 | O27: Laurientè | Q27: 16 | S27: Scamacca | U27: 30
C28: Nzola | E28: 20 | G28: Davis K. | I28: 22 | K28: Lukaku | M28: 31 | O28: Cambiaghi | Q28: 1 | S28: Giovane | U28: 3
C29: Orban G. | E29: 1 | G29: Camarda | I29: 12 | K29: Simeone | M29: 4 | O29: Belotti | Q29: 4 | S29: Colombo | U29: 6
C30: Sulemana K. | E30: 1 | F30: =SUM(E25:E30) -> 237 | G30: Cutrone | I30: 1 | J30: =SUM(I25:I30) -> 209 | K30: Lang | M30: 4 | N30: =SUM(M25:M30) -> 275 | O30: Stulic | Q30: 1 | R30: =SUM(Q25:Q30) -> 134 | S30: Pedro | U30: 1 | V30: =SUM(U25:U30) -> 286
C31: TOT SPESO | E31: =SUM(E6:E30) -> 498 | G31: TOT SPESO | I31: =SUM(I6:I30) -> 497 | K31: TOT SPESO | M31: =SUM(M6:M30) -> 487 | O31: TOT SPESO | Q31: =SUM(Q6:Q30) -> 490 | S31: TOT SPESO | U31: =SUM(U6:U30) -> 498
C32: RIMANENTI | E32: =500-E31 -> 2 | G32: RIMANENTI | I32: =500-I31 -> 3 | K32: RIMANENTI | M32: =500-M31 -> 13 | O32: RIMANENTI | Q32: =500-Q31 -> 10 | S32: RIMANENTI | U32: =500-U31 -> 2
C39: CARLSBERG | G39: FATTE | K39: LOMBA LGIA | O39: NEWB | S39: FUSTOLOTTI | W39: gay
C40: GIOCATORE | E40: PREZZO | F40: TOT | G40: GIOCATORE | I40: PREZZO | J40: TOT | K40: GIOCATORE | M40: PREZZO | N40: TOT | O40: GIOCATORE | Q40: PREZZO | R40: TOT | S40: GIOCATORE | U40: PREZZO | V40: TOT
C41: De Gea | E41: 40 | G41: Sommer | I41: 51 | K41: Milinkovic-Savic V. | M41: 15 | O41: Maignan | Q41: 49 | S41: Di Gregorio | U41: 54
B42: POR | C42: Butez | E42: 17 | G42: Martinez Jo. | I42: 1 | K42: Skorupski | M42: 16 | O42: Caprile | Q42: 7 | S42: Israel | U42: 4
C43: Martinelli T. | E43: 1 | F43: =SUM(E41:E43) -> 58 | G43: Sava | I43: 1 | J43: =SUM(I41:I43) -> 53 | K43: Ravaglia F. | M43: 1 | N43: =SUM(M41:M43) -> 32 | O43: Terracciano | Q43: 1 | R43: =SUM(Q41:Q43) -> 57 | S43: Perin | U43: 1 | V43: =SUM(U41:U43) -> 59
C44: Bremer | E44: 38 | G44: Dimarco | I44: 47 | K44: Akanji | M44: 17 | O44: Zortea | Q44: 18 | S44: Wesley | U44: 27
C45: Angelino | E45: 30 | G45: Dumfries | I45: 44 | K45: Angori | M45: 6 | O45: Hien | Q45: 20 | S45: Zappacosta | U45: 4
C46: Romagnoli | E46: 1 | G46: Di Lorenzo | I46: 35 | K46: Scalvini | M46: 9 | O46: Pavlovic | Q46: 11 | S46: Martin | U46: 17
B47: DIF | C47: Pongracic | E47: 1 | G47: Vitik | I47: 4 | K47: Kalulu | M47: 10 | O47: Mancini | Q47: 15 | S47: Valeri | U47: 15
C48: Valle | E48: 8 | G48: Coco | I48: 1 | K48: Biraghi | M48: 9 | O48: Carlos Augusto | Q48: 9 | S48: Acerbi | U48: 9
...

Sheet Riassunto 2026
B1: RIASSUNTO FANTAGHEIS 2025-26
E4: TAFFO | F4: FORE | G4: BURNEY | H4: ALFIO | I4: ALE
D5: POR | E5: ='ROSE 2026'!F8 -> 42 | F5: ='ROSE 2026'!J8 -> 47 | G5: ='ROSE 2026'!N8 -> 23 | H5: ='ROSE 2026'!R8 -> 32 | I5: ='ROSE 2026'!V8 -> 54
D6: DIF | E6: ='ROSE 2026'!F16 -> 100 | F6: ='ROSE 2026'!J16 -> 101 | G6: ='ROSE 2026'!N16 -> 34 | H6: ='ROSE 2026'!R16 -> 109 | I6: ='ROSE 2026'!V16 -> 66
D7: CEN | E7: ='ROSE 2026'!F24 -> 119 | F7: ='ROSE 2026'!J24 -> 140 | G7: ='ROSE 2026'!N24 -> 155 | H7: ='ROSE 2026'!R24 -> 215 | I7: ='ROSE 2026'!V24 -> 92
D8: ATT | E8: ='ROSE 2026'!F30 -> 237 | F8: ='ROSE 2026'!J30 -> 209 | G8: ='ROSE 2026'!N30 -> 275 | H8: ='ROSE 2026'!R30 -> 134 | I8: ='ROSE 2026'!V30 -> 286
D9: TOT | E9: =SUM(E5:E8) -> 498 | F9: =SUM(F5:F8) -> 497 | G9: =SUM(G5:G8) -> 487 | H9: =SUM(H5:H8) -> 490 | I9: =SUM(I5:I8) -> 498
D10: RIMANENTI | E10: =500-E9 -> 2 | F10: =500-F9 -> 3 | G10: =500-G9 -> 13 | H10: =500-H9 -> 10 | I10: =500-I9 -> 2
E12: CARL | F12: ISMO | G12: LOMBA | H12: NIUB | I12: FUSTOLOTTI
D13: POR | E13: ='ROSE 2026'!F43 -> 58 | F13: ='ROSE 2026'!J43 -> 53 | G13: ='ROSE 2026'!N43 -> 32 | H13: ='ROSE 2026'!R43 -> 57 | I13: ='ROSE 2026'!V43 -> 59
D14: DIF | E14: ='ROSE 2026'!F51 -> 86 | F14: ='ROSE 2026'!J51 -> 134 | G14: ='ROSE 2026'!N51 -> 67 | H14: ='ROSE 2026'!R51 -> 108 | I14: ='ROSE 2026'!V51 -> 80
D15: CEN | E15: ='ROSE 2026'!F59 -> 74 | F15: ='ROSE 2026'!J59 -> 164 | G15: ='ROSE 2026'!N59 -> 142 | H15: ='ROSE 2026'!R59 -> 122 | I15: ='ROSE 2026'!V59 -> 131
D16: ATT | E16: ='ROSE 2026'!F65 -> 267 | F16: ='ROSE 2026'!J65 -> 149 | G16: ='ROSE 2026'!N65 -> 258 | H16: ='ROSE 2026'!R65 -> 208 | I16: ='ROSE 2026'!V65 -> 230
D17: TOT | E17: =SUM(E13:E16) -> 485 | F17: =SUM(F13:F16) -> 500 | G17: =SUM(G13:G16) -> 499 | H17: =SUM(H13:H16) -> 495 | I17: =SUM(I13:I16) -> 500
D18: RIMANENTI | E18: =500-E17 -> 15 | F18: =500-F17 -> 0 | G18: =500-G17 -> 1 | H18: =500-H17 -> 5 | I18: =500-I17 -> 0

Sheet Riassunto Rose
A1: Fantallenatore | B1: giocatore | C1: quota | D1: Ruolo
A2: Taffo | B2: ='ROSE 2026'!C6 -> Carnesecchi | C2: ='ROSE 2026'!E6 -> 40 | D2: P
A3: Taffo | B3: ='ROSE 2026'!C7 -> Sportiello | C3: ='ROSE 2026'!E7 -> 1 | D3: P
A4: Taffo | B4: ='ROSE 2026'!C8 -> Okoye | C4: ='ROSE 2026'!E8 -> 1 | D4: P
A5: Taffo | B5: ='ROSE 2026'!C9 -> Bastoni | C5: ='ROSE 2026'!E9 -> 35 | D5: D
A6: Taffo | B6: ='ROSE 2026'!C10 -> Miranda J. | C6: ='ROSE 2026'!E10 -> 16 | D6: D
A7: Taffo | B7: ='ROSE 2026'!C11 -> Solet | C7: ='ROSE 2026'!E11 -> 25 | D7: D
A8: Taffo | B8: ='ROSE 2026'!C12 -> Vasquez | C8: ='ROSE 2026'!E12 -> 12 | D8: D
A9: Taffo | B9: ='ROSE 2026'!C13 -> Gabbia | C9: ='ROSE 2026'!E13 -> 4 | D9: D
A10: Taffo | B10: ='ROSE 2026'!C14 -> Gallo | C10: ='ROSE 2026'!E14 -> 5 | D10: D
A11: Taffo | B11: ='ROSE 2026'!C15 -> Ismajli | C11: ='ROSE 2026'!E15 -> 2 | D11: D
A12: Taffo | B12: ='ROSE 2026'!C16 -> Kelly L. | C12: ='ROSE 2026'!E16 -> 1 | D12: D
A13: Taffo | B13: ='ROSE 2026'!C17 -> Conceicao | C13: ='ROSE 2026'!E17 -> 36 | D13: C
... A26: Taffo | B26: ='ROSE 2026'!C30 -> Sulemana K. | C26: ='ROSE 2026'!E30 -> 1 | D26: A
A27: Fore | B27: ='ROSE 2026'!G6 -> Meret | C27: ='ROSE 2026'!I6 -> 44 | D27: P
A28: Fore | B28: ='ROSE 2026'!G7 -> Audero | C28: ='ROSE 2026'!I7 -> 2 | D28: P
A29: Fore | B29: ='ROSE 2026'!G8 -> Montipò | C29: ='ROSE 2026'!I8 -> 1 | D29: P
A30: Fore | B30: ='ROSE 2026'!G9 -> Gosens | C30: ='ROSE 2026'!I9 -> 40 | D30: D
A31: Fore | B31: ='ROSE 2026'!G10 -> Bellanova | C31: ='ROSE 2026'!I10 -> 35 | D31: D
A32: Fore | B32: ='ROSE 2026'!G11 -> De Winter | C32: ='ROSE 2026'!I11 -> 3 | D32: D
A33: Fore | B33: ='ROSE 2026'!G12 -> Delprato | C33: ='ROSE 2026'!I12 -> 13 | D33: D
A34: Fore | B34: ='ROSE 2026'!G13 -> Comuzzo | C34: ='ROSE 2026'!I13 -> 4 | D34: D
A35: Fore | B35: ='ROSE 2026'!G14 -> Ranieri L. | C35: ='ROSE 2026'!I14 -> 4 | D35: D
A36: Fore | B36: ='ROSE 2026'!G15 -> Kristensen T. | C36: ='ROSE 2026'!I15 -> 1 | D36: D
A37: Fore | B37: ='ROSE 2026'!G16 -> Ahanor | C37: ='ROSE 2026'!I16 -> 1 | D37: D
A38: Fore | B38: ='ROSE 2026'!G17 -> Orsolini | C38: ='ROSE 2026'!I17 -> 70 | D38: C
... A51: Fore | B51: ='ROSE 2026'!G30 -> Cutrone | C51: ='ROSE 2026'!I30 -> 1 | D51: A
A52: Burney | B52: ='ROSE 2026'!K6 -> Leali | C52: ='ROSE 2026'!M6 -> 8 | D52: P
A53: Burney | B53: ='ROSE 2026'!K7 -> Semper | C53: ='ROSE 2026'!M7 -> 2 | D53: P
A54: Burney | B54: ='ROSE 2026'!K8 -> Suzuki | C54: ='ROSE 2026'!M8 -> 13 | D54: P
A55: Burney | B55: ='ROSE 2026'!K9 -> Gila | C55: ='ROSE 2026'!M9 -> 8 | D55: D
A56: Burney | B56: ='ROSE 2026'!K10 -> Tomori | C56: ='ROSE 2026'!M10 -> 5 | D56: D
A57: Burney | B57: ='ROSE 2026'!K11 -> Gatti | C57: ='ROSE 2026'!M11 -> 7 | D57: D
A58: Burney | B58: ='ROSE 2026'!K12 -> Palestra | C58: ='ROSE 2026'!M12 -> 5 | D58: D
A59: Burney | B59: ='ROSE 2026'!K13 -> De Vrij | C59: ='ROSE 2026'!M13 -> 2 | D59: D
A60: Burney | B60: ='ROSE 2026'!K14 -> Pezzella Giu. | C60: ='ROSE 2026'!M14 -> 1 | D60: D
A61: Burney | B61: ='ROSE 2026'!K15 -> Doig | C61: ='ROSE 2026'!M15 -> 4 | D61: D
A62: Burney | B62: ='ROSE 2026'!K16 -> Hermoso | C62: ='ROSE 2026'!M16 -> 2 | D62: D
A63: Burney | B63: ='ROSE 2026'!K17 -> Zaccagni | C63: ='ROSE 2026'!M17 -> 80 | D63: C
... A76: Burney | B76: ='ROSE 2026'!K30 -> Lang | C76: ='ROSE 2026'!M30 -> 4 | D76: A
...

Sheet Lista
A1: Id | B1: R | C1: RM | D1: Nome | E1: Squadra | F1: Qt.A | G1: Qt.I | H1: Diff. | I1: Qt.A M | J1: Qt.I M | K1: Diff.M | L1: FVM | M1: FVM M
A2: 4312 | B2: P | C2: Por | D2: Maignan | E2: Milan | F2: 20 | G2: 16 | H2: 4 | I2: 20 | J2: 16 | K2: 4 | L2: 90 | M2: 90
A3: 5841 | B3: P | C3: Por | D3: Svilar | E3: Roma | F3: 19 | G3: 15 | H3: 4 | I3: 19 | J3: 15 | K3: 4 | L3: 101 | M3: 101
A4: 4431 | B4: P | C4: Por | D4: Carnesecchi | E4: Atalanta | F4: 18 | G4: 14 | H4: 4 | I4: 18 | J4: 14 | K4: 4 | L4: 62 | M4: 62
A5: 2170 | B5: P | C5: Por | D5: Milinkovic-Savic V. | E5: Napoli | F5: 18 | G5: 4 | H5: 14 | I5: 18 | J5: 4 | K5: 14 | L5: 45 | M5: 45
A6: 6966 | B6: P | C6: Por | D6: Butez | E6: Como | F6: 17 | G6: 10 | H6: 7 | I6: 17 | J6: 10 | K6: 7 | L6: 70 | M6: 70
A7: 2814 | B7: P | C7: Por | D7: Provedel | E7: Lazio | F7: 17 | G7: 12 | H7: 5 | I7: 17 | J7: 12 | K7: 5 | L7: 74 | M7: 74
A8: 5876 | B8: P | C8: Por | D8: Di Gregorio | E8: Juventus | F8: 16 | G8: 16 | H8: 0 | I8: 16 | J8: 16 | K8: 0 | L8: 68 | M8: 68
A9: 2134 | B9: P | C9: Por | D9: Falcone | E9: Lecce | F9: 16 | G9: 6 | H9: 10 | I9: 16 | J9: 6 | K9: 10 | L9: 38 | M9: 38
A10: 761 | B10: P | C10: Por | D10: Audero | E10: Cremonese | F10: 15 | G10: 5 | H10: 10 | I10: 15 | J10: 5 | K10: 10 | L10: 14 | M10: 14
A11: 2428 | B11: P | C11: Por | D11: Sommer | E11: Inter | F11: 13 | G11: 16 | H11: -3 | I11: 13 | J11: 16 | K11: -3 | L11: 57 | M11: 57
A12: 4360 | B12: P | C12: Por | D12: Caprile | E12: Cagliari | F12: 12 | G12: 7 | H12: 5 | I12: 12 | J12: 7 | K12: 5 | L12: 26 | M12: 26
A13: 4236 | B13: P | C13: Por | D13: Muric | E13: Sassuolo | F13: 12 | G13: 3 | H13: 9 | I13: 12 | J13: 3 | K13: 9 | L13: 15 | M13: 15
... A547: 7317 | B547: A | C547: Pc | D547: Trepy | E547: Cagliari | F547: 1 | G547: 1 | H547: 0 | I547: 1 | J547: 1 | K547: 0 | L547: 1 | M547: 1

Sheet LISTA SVINCOLATI
C1: SVINCOLATI
K2: NOTA BENE: ROSSO = NON TOCCARE! SI COMPILA DA SOLO
C3: COMPILA | D3: COMPILA | E3: COMPILA | F3: NON TOCCARE | G3: NON TOCCARE | H3: NON TOCCARE | I3: NON TOCCARE
A4: Nomi fantallenatori da usare | C4: Fantallenatore | D4: Giocatore da svincolare | E4: E' andato all'estero? | F4: Ruolo | G4: Prezzo D'acquisto asta | H4: Prezzo Q.A.Fantacalcio | I4: Prezzo svincolo | K4: LEGENDA:
A5: Taffo | C5: Taffo | D5: Mkhitaryan | E5: No | F5: =IFERROR(VLOOKUP(D5,'Riassunto Rose'!$B$2:$D$251,3,FALSE),"") -> C | G5: =IFERROR(VLOOKUP(D5,'Riassunto Rose'!$B$2:$C$251,2,FALSE),"") -> 1 | H5: =IFERROR(VLOOKUP(D5,Lista!$D$1:$F$1998,3,FALSE),"") -> 10 | I5: =round(if(E5="No",min(G5,H5*2)/2,G5),0) -> 1 | K5: Nome Fantallenatore: inserite il vostro nome ( vi chiedo cortesemente di inserire il nome che trovate a fianco della tabella)
A6: Fore | C6: Taffo | D6: Sucic P. | E6: No | F6: =IFERROR(VLOOKUP(D6,'Riassunto Rose'!$B$2:$D$251,3,FALSE),"") -> C | G6: =IFERROR(VLOOKUP(D6,'Riassunto Rose'!$B$2:$C$251,2,FALSE),"") -> 13 | H6: =IFERROR(VLOOKUP(D6,Lista!$D$1:$F$1998,3,FALSE),"") -> 11 | I6: =round(if(E6="No",min(G6,H6*2)/2,G6),0) -> 7 | K6: Giocatore da svincolare: scrivete il nome del giocatore che volete svincolare o che è andato all'estero (appena appare il nome dopo aver digitato i primi caratteri, selezionatelo
A7: Burney | C7: Taffo | D7: Bernardeschi | E7: No | F7: =IFERROR(VLOOKUP(D7,'Riassunto Rose'!$B$2:$D$251,3,FALSE),"") -> C | G7: =IFERROR(VLOOKUP(D7,'Riassunto Rose'!$B$2:$C$251,2,FALSE),"") -> 1 | H7: =IFERROR(VLOOKUP(D7,Lista!$D$1:$F$1998,3,FALSE),"") -> 5 | I7: =round(if(E7="No",min(G7,H7*2)/2,G7),0) -> 1 | K7: E' Andato all'estero?: è una variabile binaria; mettete Si se è andato all'estero, altrimenti No
A8: Alfio | C8: Taffo | D8: Nzola | E8: No | F8: =IFERROR(VLOOKUP(D8,'Riassunto Rose'!$B$2:$D$251,3,FALSE),"") -> A | G8: =IFERROR(VLOOKUP(D8,'Riassunto Rose'!$B$2:$C$251,2,FALSE),"") -> 20 | H8: =IFERROR(VLOOKUP(D8,Lista!$D$1:$F$1998,3,FALSE),"") -> 11 | I8: =round(if(E8="No",min(G8,H8*2)/2,G8),0) -> 10 | K8: Prezzo D'acquisto asta: Inserisce il prezzo in automatico a cui avete acquistato il giocatore nell'asta ad inizio anno. Potete prendere il suo valore nel foglio ROSE.
A9: Ale | C9: Taffo | D9: Sulemana K. | E9: No | F9: =IFERROR(VLOOKUP(D9,'Riassunto Rose'!$B$2:$D$251,3,FALSE),"") -> A | G9: =IFERROR(VLOOKUP(D9,'Riassunto Rose'!$B$2:$C$251,2,FALSE),"") -> 1 | H9: =IFERROR(VLOOKUP(D9,Lista!$D$1:$F$1998,3,FALSE),"") -> 11 | I9: =round(if(E9="No",min(G9,H9*2)/2,G9),0) -> 1 | K9: Prezzo Quota Attuale Fantacalcio: Prende il prezzo attuale Q.a. in automatico( attenzione non iniziale Q.i.) che trovate nel sito di Fantacalcio indicato sotto in questo foglio.
A10: Carl | C10: Carl | D10: Joao Mario | E10: No | F10: =IFERROR(VLOOKUP(D10,'Riassunto Rose'!$B$2:$D$251,3,FALSE),"") -> D | G10: =IFERROR(VLOOKUP(D10,'Riassunto Rose'!$B$2:$C$251,2,FALSE),"") -> 6 | H10: =IFERROR(VLOOKUP(D10,Lista!$D$1:$F$1998,3,FALSE),"") -> 2 | I10: =round(if(E10="No",min(G10,H10*2)/2,G10),0) -> 2 | K10: Prezzo Svincolo: sarà il prezzo che recupererete effettivamente dallo svincolo del giocatore, è una formula non va compilato
A11: Ismo | C11: Carl | D11: Stengs | E11: No | F11: =IFERROR(VLOOKUP(D11,'Riassunto Rose'!$B$2:$D$251,3,FALSE),"") -> C | G11: =IFERROR(VLOOKUP(D11,'Riassunto Rose'!$B$2:$C$251,2,FALSE),"") -> 1 | H11: =IFERROR(VLOOKUP(D11,Lista!$D$1:$F$1998,3,FALSE),"") -> 1 | I11: =round(if(E11="No",min(G11,H11*2)/2,G11),0) -> 1
A12: Lomba | C12: Carl | D12: Sanabria | E12: No | F12: =IFERROR(VLOOKUP(D12,'Riassunto Rose'!$B$2:$D$251,3,FALSE),"") -> A | G12: =IFERROR(VLOOKUP(D12,'Riassunto Rose'!$B$2:$C$251,2,FALSE),"") -> 1 | H12: =IFERROR(VLOOKUP(D12,Lista!$D$1:$F$1998,3,FALSE),"") -> 6 | I12: =round(if(E12="No",min(G12,H12*2)/2,G12),0) -> 1
A13: Niub | C13: Carl | D13: Martinelli T. | E13: Si | F13: =IFERROR(VLOOKUP(D13,'Riassunto Rose'!$B$2:$D$251,3,FALSE),"") -> P | G13: =IFERROR(VLOOKUP(D13,'Riassunto Rose'!$B$2:$C$251,2,FALSE),"") -> 1 | H13: =IFERROR(VLOOKUP(D13,Lista!$D$1:$F$1998,3,FALSE),"") | I13: =round(if(E13="No",min(G13,H13*2)/2,G13),0) -> 1
A14: Fusto | C14: Carl | D14: Bailey | E14: Si | F14: =IFERROR(VLOOKUP(D14,'Riassunto Rose'!$B$2:$D$251,3,FALSE),"") -> C | G14: =IFERROR(VLOOKUP(D14,'Riassunto Rose'!$B$2:$C$251,2,FALSE),"") -> 6 | H14: =IFERROR(VLOOKUP(D14,Lista!$D$1:$F$1998,3,FALSE),"") | I14: =round(if(E14="No",min(G14,H14*2)/2,G14),0) -> 6 | K14: LINK QUOTAZIONI
C15: Alfio | D15: Mandas | E15: Si | F15: =IFERROR(VLOOKUP(D15,'Riassunto Rose'!$B$2:$D$251,3,FALSE),"") -> P | G15: =IFERROR(VLOOKUP(D15,'Riassunto Rose'!$B$2:$C$251,2,FALSE),"") -> 2 | H15: =IFERROR(VLOOKUP(D15,Lista!$D$1:$F$1998,3,FALSE),"") | I15: =round(if(E15="No",min(G15,H15*2)/2,G15),0) -> 2 | K15: https://www.fantacalcio.it/quotazioni-fantacalcio
C16: Alfio | D16: Castellanos | E16: Si | F16: =IFERROR(VLOOKUP(D16,'Riassunto Rose'!$B$2:$D$251,3,FALSE),"") -> A | G16: =IFERROR(VLOOKUP(D16,'Riassunto Rose'!$B$2:$C$251,2,FALSE),"") -> 101 | H16: =IFERROR(VLOOKUP(D16,Lista!$D$1:$F$1998,3,FALSE),"") | I16: =round(if(E16="No",min(G16,H16*2)/2,G16),0) -> 101 | K16: (Oppure guardate il foglio Lista che mi occuperò personalmente di aggiornare)
C17: Alfio | D17: Gronbaek | E17: Si | F17: =IFERROR(VLOOKUP(D17,'Riassunto Rose'!$B$2:$D$251,3,FALSE),"") -> C | G17: =IFERROR(VLOOKUP(D17,'Riassunto Rose'!$B$2:$C$251,2,FALSE),"") -> 2 | H17: =IFERROR(VLOOKUP(D17,Lista!$D$1:$F$1998,3,FALSE),"") | I17: =round(if(E17="No",min(G17,H17*2)/2,G17),0) -> 2
C18: Alfio | D18: Belotti | E18: No | F18: =IFERROR(VLOOKUP(D18,'Riassunto Rose'!$B$2:$D$251,3,FALSE),"") -> A | G18: =IFERROR(VLOOKUP(D18,'Riassunto Rose'!$B$2:$C$251,2,FALSE),"") -> 4 | H18: =IFERROR(VLOOKUP(D18,Lista!$D$1:$F$1998,3,FALSE),"") -> 8 | I18: =round(if(E18="No",min(G18,H18*2)/2,G18),0) -> 2
A19: GIALLO: SVINCOLATO | C19: Ale | D19: Estupinan | E19: No | F19: =IFERROR(VLOOKUP(D19,'Riassunto Rose'!$B$2:$D$251,3,FALSE),"") -> D | G19: =IFERROR(VLOOKUP(D19,'Riassunto Rose'!$B$2:$C$251,2,FALSE),"") -> 9 | H19: =IFERROR(VLOOKUP(D19,Lista!$D$1:$F$1998,3,FALSE),"") -> 3 | I19: =round(if(E19="No",min(G19,H19*2)/2,G19),0) -> 3
C20: Ale | D20: El Aynaoui | E20: No | F20: =IFERROR(VLOOKUP(D20,'Riassunto Rose'!$B$2:$D$251,3,FALSE),"") -> C | G20: =IFERROR(VLOOKUP(D20,'Riassunto Rose'!$B$2:$C$251,2,FALSE),"") -> 1 | H20: =IFERROR(VLOOKUP(D20,Lista!$D$1:$F$1998,3,FALSE),"") -> 4 | I20: =round(if(E20="No",min(G20,H20*2)/2,G20),0) -> 1 | K20: Nel foglio RIASSUNTO SVINCOLATI, saprete il numero giocatori svincolati e quindi da acquistare
C21: Carl | D21: Rovella | E21: No | F21: =IFERROR(VLOOKUP(D21,'Riassunto Rose'!$B$2:$D$251,3,FALSE),"") -> C | G21: =IFERROR(VLOOKUP(D21,'Riassunto Rose'!$B$2:$C$251,2,FALSE),"") -> 5 | H21: =IFERROR(VLOOKUP(D21,Lista!$D$1:$F$1998,3,FALSE),"") -> 3 | I21: =round(if(E21="No",min(G21,H21*2)/2,G21),0) -> 3 | K21: al mercato riparazione. Non dovrete fare altro che compilare solamente questa tabella svincolati come indicato.
C22: Fore | D22: Cutrone | E22: Si | F22: =IFERROR(VLOOKUP(D22,'Riassunto Rose'!$B$2:$D$251,3,FALSE),"") -> A | G22: =IFERROR(VLOOKUP(D22,'Riassunto Rose'!$B$2:$C$251,2,FALSE),"") -> 1 | H22: =IFERROR(VLOOKUP(D22,Lista!$D$1:$F$1998,3,FALSE),"") | I22: =round(if(E22="No",min(G22,H22*2)/2,G22),0) -> 1
C23: Fore | D23: Lucca | E23: Si | F23: =IFERROR(VLOOKUP(D23,'Riassunto Rose'!$B$2:$D$251,3,FALSE),"") -> A | G23: =IFERROR(VLOOKUP(D23,'Riassunto Rose'!$B$2:$C$251,2,FALSE),"") -> 15 | H23: =IFERROR(VLOOKUP(D23,Lista!$D$1:$F$1998,3,FALSE),"") | I23: =round(if(E23="No",min(G23,H23*2)/2,G23),0) -> 15
C24: Fore | D24: Camarda | E24: No | F24: =IFERROR(VLOOKUP(D24,'Riassunto Rose'!$B$2:$D$251,3,FALSE),"") -> A | G24: =IFERROR(VLOOKUP(D24,'Riassunto Rose'!$B$2:$C$251,2,FALSE),"") -> 12 | H24: =IFERROR(VLOOKUP(D24,Lista!$D$1:$F$1998,3,FALSE),"") -> 4 | I24: =round(if(E24="No",min(G24,H24*2)/2,G24),0) -> 4
C25: Ismo | D25: Bravo | E25: Si | F25: =IFERROR(VLOOKUP(D25,'Riassunto Rose'!$B$2:$D$251,3,FALSE),"") -> A | G25: =IFERROR(VLOOKUP(D25,'Riassunto Rose'!$B$2:$C$251,2,FALSE),"") -> 1 | H25: =IFERROR(VLOOKUP(D25,Lista!$D$1:$F$1998,3,FALSE),"") | I25: =round(if(E25="No",min(G25,H25*2)/2,G25),0) -> 1 | K25: FORMULA SVINCOLO GIOCATORE:
C26: Ismo | D26: Pierotti | E26: No | F26: =IFERROR(VLOOKUP(D26,'Riassunto Rose'!$B$2:$D$251,3,FALSE),"") -> C | G26: =IFERROR(VLOOKUP(D26,'Riassunto Rose'!$B$2:$C$251,2,FALSE),"") -> 2 | H26: =IFERROR(VLOOKUP(D26,Lista!$D$1:$F$1998,3,FALSE),"") -> 6 | I26: =round(if(E26="No",min(G26,H26*2)/2,G26),0) -> 1 | K26: Prezzo svincolo = min(Prezzo d'acquisto asta, (Prezzo Q.a. Fantalcalcio)*2)/2
C27: Ismo | D27: Vitik | E27: No | F27: =IFERROR(VLOOKUP(D27,'Riassunto Rose'!$B$2:$D$251,3,FALSE),"") -> D | G27: =IFERROR(VLOOKUP(D27,'Riassunto Rose'!$B$2:$C$251,2,FALSE),"") -> 4 | H27: =IFERROR(VLOOKUP(D27,Lista!$D$1:$F$1998,3,FALSE),"") -> 4 | I27: =round(if(E27="No",min(G27,H27*2)/2,G27),0) -> 2 | K27: ( il *2 è dovuto perchè le quotazioni Fantacalcio sono tarate su 250, mentre le nostre su 500
C28: Ismo | D28: Sava | E28: No | F28: =IFERROR(VLOOKUP(D28,'Riassunto Rose'!$B$2:$D$251,3,FALSE),"") -> P | G28: =IFERROR(VLOOKUP(D28,'Riassunto Rose'!$B$2:$C$251,2,FALSE),"") -> 1 | H28: =IFERROR(VLOOKUP(D28,Lista!$D$1:$F$1998,3,FALSE),"") -> 1 | I28: =round(if(E28="No",min(G28,H28*2)/2,G28),0) -> 1
C29: Fusto | D29: Vazquez | E29: Si | F29: =IFERROR(VLOOKUP(D29,'Riassunto Rose'!$B$2:$D$251,3,FALSE),"") -> C | G29: =IFERROR(VLOOKUP(D29,'Riassunto Rose'!$B$2:$C$251,2,FALSE),"") -> 23 | H29: =IFERROR(VLOOKUP(D29,Lista!$D$1:$F$1998,3,FALSE),"") | I29: =round(if(E29="No",min(G29,H29*2)/2,G29),0) -> 23
C30: Fusto | D30: Immobile | E30: Si | F30: =IFERROR(VLOOKUP(D30,'Riassunto Rose'!$B$2:$D$251,3,FALSE),"") -> A | G30: =IFERROR(VLOOKUP(D30,'Riassunto Rose'!$B$2:$C$251,2,FALSE),"") -> 6 | H30: =IFERROR(VLOOKUP(D30,Lista!$D$1:$F$1998,3,FALSE),"") | I30: =round(if(E30="No",min(G30,H30*2)/2,G30),0) -> 6
C31: Fusto | D31: Dzeko | E31: Si | F31: =IFERROR(VLOOKUP(D31,'Riassunto Rose'!$B$2:$D$251,3,FALSE),"") -> A | G31: =IFERROR(VLOOKUP(D31,'Riassunto Rose'!$B$2:$C$251,2,FALSE),"") -> 14 | H31: =IFERROR(VLOOKUP(D31,Lista!$D$1:$F$1998,3,FALSE),"") | I31: =round(if(E31="No",min(G31,H31*2)/2,G31),0) -> 14
C32: Fusto | D32: Dovbyk | E32: No | F32: =IFERROR(VLOOKUP(D32,'Riassunto Rose'!$B$2:$D$251,3,FALSE),"") -> A | G32: =IFERROR(VLOOKUP(D32,'Riassunto Rose'!$B$2:$C$251,2,FALSE),"") -> 41 | H32: =IFERROR(VLOOKUP(D32,Lista!$D$1:$F$1998,3,FALSE),"") -> 14 | I32: =round(if(E32="No",min(G32,H32*2)/2,G32),0) -> 14
C33: Fusto | D33: Piccoli | E33: No | F33: =IFERROR(VLOOKUP(D33,'Riassunto Rose'!$B$2:$D$251,3,FALSE),"") -> A | G33: =IFERROR(VLOOKUP(D33,'Riassunto Rose'!$B$2:$C$251,2,FALSE),"") -> 19 | H33: =IFERROR(VLOOKUP(D33,Lista!$D$1:$F$1998,3,FALSE),"") -> 8 | I33: =round(if(E33="No",min(G33,H33*2)/2,G33),0) -> 8
C34: Fusto | D34: Dele-Bashiru | E34: No | F34: =IFERROR(VLOOKUP(D34,'Riassunto Rose'!$B$2:$D$251,3,FALSE),"") -> C | G34: =IFERROR(VLOOKUP(D34,'Riassunto Rose'!$B$2:$C$251,2,FALSE),"") -> 5 | H34: =IFERROR(VLOOKUP(D34,Lista!$D$1:$F$1998,3,FALSE),"") -> 3 | I34: =round(if(E34="No",min(G34,H34*2)/2,G34),0) -> 3
C35: Fusto | D35: Israel | E35: No | F35: =IFERROR(VLOOKUP(D35,'Riassunto Rose'!$B$2:$D$251,3,FALSE),"") -> P | G35: =IFERROR(VLOOKUP(D35,'Riassunto Rose'!$B$2:$C$251,2,FALSE),"") -> 4 | H35: =IFERROR(VLOOKUP(D35,Lista!$D$1:$F$1998,3,FALSE),"") -> 2 | I35: =round(if(E35="No",min(G35,H35*2)/2,G35),0) -> 2
C36: Niub | D36: Ngonge | E36: Si | F36: =IFERROR(VLOOKUP(D36,'Riassunto Rose'!$B$2:$D$251,3,FALSE),"") -> A | G36: =IFERROR(VLOOKUP(D36,'Riassunto Rose'!$B$2:$C$251,2,FALSE),"") -> 14 | H36: =IFERROR(VLOOKUP(D36,Lista!$D$1:$F$1998,3,FALSE),"") | I36: =round(if(E36="No",min(G36,H36*2)/2,G36),0) -> 14
C37: Niub | D37: Carboni V. | E37: Si | F37: =IFERROR(VLOOKUP(D37,'Riassunto Rose'!$B$2:$D$251,3,FALSE),"") -> C | G37: =IFERROR(VLOOKUP(D37,'Riassunto Rose'!$B$2:$C$251,2,FALSE),"") -> 9 | H37: =IFERROR(VLOOKUP(D37,Lista!$D$1:$F$1998,3,FALSE),"") | I37: =round(if(E37="No",min(G37,H37*2)/2,G37),0) -> 9
C38: Niub | D38: Asllani | E38: Si | F38: =IFERROR(VLOOKUP(D38,'Riassunto Rose'!$B$2:$D$251,3,FALSE),"") -> C | G38: =IFERROR(VLOOKUP(D38,'Riassunto Rose'!$B$2:$C$251,2,FALSE),"") -> 1 | H38: =IFERROR(VLOOKUP(D38,Lista!$D$1:$F$1998,3,FALSE),"") | I38: =round(if(E38="No",min(G38,H38*2)/2,G38),0) -> 1
C39: Burney | D39: Semper | E39: No | F39: =IFERROR(VLOOKUP(D39,'Riassunto Rose'!$B$2:$D$251,3,FALSE),"") -> P | G39: =IFERROR(VLOOKUP(D39,'Riassunto Rose'!$B$2:$C$251,2,FALSE),"") -> 2 | H39: =IFERROR(VLOOKUP(D39,Lista!$D$1:$F$1998,3,FALSE),"") -> 9 | I39: =round(if(E39="No",min(G39,H39*2)/2,G39),0) -> 1
... C53: Taffo | D53: Ismajli | E53: No | F53: =IFERROR(VLOOKUP(D53,'Riassunto Rose'!$B$2:$D$251,3,FALSE),"") -> D | G53: =IFERROR(VLOOKUP(D53,'Riassunto Rose'!$B$2:$C$251,2,FALSE),"") -> 2 | H53: =IFERROR(VLOOKUP(D53,Lista!$D$1:$F$1998,3,FALSE),"") -> 6 | I53: =round(if(E53="No",min(G53,H53*2)/2,G53),0) -> 1
...

Sheet RIASSUNTO SVINCOLATI
B2: RIASSUNTO FANTAMILIONI
J3: RUOLI SVINCOLATI | Q3: RUOLI RIMPIAZZATI | X3: RUOLI RIMANENTI
C4: NON TOCCARE | D4: NON TOCCARE | F4: NON TOCCARE | G4: NON TOCCARE | H4: NON TOCCARE | K4: NON TOCCARE | L4: NON TOCCARE | M4: NON TOCCARE | N4: NON TOCCARE | O4: NON TOCCARE | R4: NON TOCCARE | S4: NON TOCCARE | T4: NON TOCCARE | U4: NON TOCCARE | V4: NON TOCCARE | Y4: NON TOCCARE | Z4: NON TOCCARE | AA4: NON TOCCARE | AB4: NON TOCCARE | AC4: NON TOCCARE
B5: Fantallenatore | C5: Numero giocatori svincolati | D5: Guadagno da svincoli | F5: Soldi rimanenti dall'asta | G5: Soldi aggiuntivi per l'asta di riparazione | H5: Fantamilioni a disposizione | J5: Fantallenatore | K5: P | L5: D | M5: C | N5: A | O5: TOT | Q5: Fantallenatore | R5: P | S5: D | T5: C | U5: A | V5: TOT | X5: Fantallenatore | Y5: P | Z5: D | AA5: C | AB5: A | AC5: TOT
B6: ='LISTA SVINCOLATI'!$A$5 -> Taffo | C6: =O6 -> 7 | D6: =sumif('LISTA SVINCOLATI'!C$5:C$120,B6,'LISTA SVINCOLATI'!I$5:I$120) -> 27 | F6: ='ROSE 2026'!E32 -> 2 | G6: 100 | H6: =D6+F6+G6 -> 129 | J6: ='LISTA SVINCOLATI'!$A$5 -> Taffo | K6: =COUNTIFS('LISTA SVINCOLATI'!$C$4:$C$120,$J6,'LISTA SVINCOLATI'!$F$4:$F$120,K$5) -> 0 | L6: =COUNTIFS('LISTA SVINCOLATI'!$C$4:$C$120,$J6,'LISTA SVINCOLATI'!$F$4:$F$120,L$5) -> 1 | M6: =COUNTIFS('LISTA SVINCOLATI'!$C$4:$C$120,$J6,'LISTA SVINCOLATI'!$F$4:$F$120,M$5) -> 3 | N6: =COUNTIFS('LISTA SVINCOLATI'!$C$4:$C$120,$J6,'LISTA SVINCOLATI'!$F$4:$F$120,N$5) -> 3 | O6: =SUM(K6:N6) -> 7 | Q6: ='LISTA SVINCOLATI'!$A$5 -> Taffo | R6: =COUNTIF($C20:$Z20,R$5) -> 0 | S6: =COUNTIF($C20:$Z20,S$5) -> 0 | T6: =COUNTIF($C20:$Z20,T$5) -> 0 | U6: =COUNTIF($C20:$Z20,U$5) -> 0 | V6: =SUM(R6:U6) -> 0 | X6: ='LISTA SVINCOLATI'!$A$5 -> Taffo | Y6: =K6-R6 -> 0 | Z6: =L6-S6 -> 1 | AA6: =M6-T6 -> 3 | AB6: =N6-U6 -> 3 | AC6: =SUM(Y6:AB6) -> 7
B7: ='LISTA SVINCOLATI'!$A$6 -> Fore | C7: =O7 -> 3 | D7: =sumif('LISTA SVINCOLATI'!C$5:C$120,B7,'LISTA SVINCOLATI'!I$5:I$120) -> 20 | F7: ='ROSE 2026'!I32 -> 3 | G7: 100 | H7: =D7+F7+G7 -> 123 | J7: ='LISTA SVINCOLATI'!$A$6 -> Fore | K7: =COUNTIFS('LISTA SVINCOLATI'!$C$4:$C$120,$J7,'LISTA SVINCOLATI'!$F$4:$F$120,K$5) -> 0 | L7: =COUNTIFS('LISTA SVINCOLATI'!$C$4:$C$120,$J7,'LISTA SVINCOLATI'!$F$4:$F$120,L$5) -> 0 | M7: =COUNTIFS('LISTA SVINCOLATI'!$C$4:$C$120,$J7,'LISTA SVINCOLATI'!$F$4:$F$120,M$5) -> 0 | N7: =COUNTIFS('LISTA SVINCOLATI'!$C$4:$C$120,$J7,'LISTA SVINCOLATI'!$F$4:$F$120,N$5) -> 3 | O7: =SUM(K7:N7) -> 3 | Q7: ='LISTA SVINCOLATI'!$A$6 -> Fore | R7: =COUNTIF($C21:$Z21,R$5) -> 0 | S7: =COUNTIF($C21:$Z21,S$5) -> 0 | T7: =COUNTIF($C21:$Z21,T$5) -> 0 | U7: =COUNTIF($C21:$Z21,U$5) -> 0 | V7: =SUM(R7:U7) -> 0 | X7: ='LISTA SVINCOLATI'!$A$6 -> Fore | Y7: =K7-R7 -> 0 | Z7: =L7-S7 -> 0 | AA7: =M7-T7 -> 0 | AB7: =N7-U7 -> 3 | AC7: =SUM(Y7:AB7) -> 3
B8: ='LISTA SVINCOLATI'!$A$7 -> Burney | C8: =O8 -> 6 | D8: =sumif('LISTA SVINCOLATI'!C$5:C$120,B8,'LISTA SVINCOLATI'!I$5:I$120) -> 23 | F8: ='ROSE 2026'!M32 -> 13 | G8: 100 | H8: =D8+F8+G8 -> 136 | J8: ='LISTA SVINCOLATI'!$A$7 -> Burney | K8: =COUNTIFS('LISTA SVINCOLATI'!$C$4:$C$120,$J8,'LISTA SVINCOLATI'!$F$4:$F$120,K$5) -> 2 | L8: =COUNTIFS('LISTA SVINCOLATI'!$C$4:$C$120,$J8,'LISTA SVINCOLATI'!$F$4:$F$120,L$5) -> 1 | M8: =COUNTIFS('LISTA SVINCOLATI'!$C$4:$C$120,$J8,'LISTA SVINCOLATI'!$F$4:$F$120,M$5) -> 2 | N8: =COUNTIFS('LISTA SVINCOLATI'!$C$4:$C$120,$J8,'LISTA SVINCOLATI'!$F$4:$F$120,N$5) -> 1 | O8: =SUM(K8:N8) -> 6 | Q8: ='LISTA SVINCOLATI'!$A$7 -> Burney | R8: =COUNTIF($C22:$Z22,R$5) -> 0 | S8: =COUNTIF($C22:$Z22,S$5) -> 0 | T8: =COUNTIF($C22:$Z22,T$5) -> 0 | U8: =COUNTIF($C22:$Z22,U$5) -> 0 | V8: =SUM(R8:U8) -> 0 | X8: ='LISTA SVINCOLATI'!$A$7 -> Burney | Y8: =K8-R8 -> 2 | Z8: =L8-S8 -> 1 | AA8: =M8-T8 -> 2 | AB8: =N8-U8 -> 1 | AC8: =SUM(Y8:AB8) -> 6
